Workbook

Sheet Inputs
A1: Inputs: premium large-format conversion, per converted screen
A2: Blue = typed input. Black = formula. Green = link to another sheet. Change blue cells only; every other sheet recalculates from this one.
A3: Model sheet scenario: 1 Base, 2 Upside, 3 Downside | B3: 1 | C3: =CHOOSE(B3,"Base","Upside","Downside") -> Base
A5: A. Public figures
A6: Item | B6: Value | F6: Unit | G6: Source
A7: U.S. markets admissions revenue, 2025 | B7: 1992 | F7: $ millions | G7: AMC Entertainment Holdings, Form 10-K for fiscal 2025 (filed 2026-02-23), p. 49, Operating Results table (U.S. Markets).
A8: U.S. markets attendance, 2025 | B8: 155810 | F8: thousands | G8: AMC Entertainment Holdings, Form 10-K for fiscal 2025 (filed 2026-02-23), p. 49, Operating Data.
A9: U.S. markets average screens, 2025 | B9: 7057 | F9: screens | G9: AMC Entertainment Holdings, Form 10-K for fiscal 2025 (filed 2026-02-23), p. 49, Operating Data.
A10: U.S. markets operating expense, excluding depreciation and amortization, 2025 | B10: 1327.1 | F10: $ millions | G10: AMC Entertainment Holdings, Form 10-K for fiscal 2025 (filed 2026-02-23), p. 49, Operating Results table.
A11: U.S. film exhibition costs as % of admissions revenue, 2025 | B11: 0.512 | F11: % | G11: AMC Entertainment Holdings, Form 10-K for fiscal 2025 (filed 2026-02-23), p. 55, Theatrical Exhibition - U.S. Markets.
A12: U.S. food and beverage costs as % of food and beverage revenue, 2025 | B12: 0.181 | F12: % | G12: AMC Entertainment Holdings, Form 10-K for fiscal 2025 (filed 2026-02-23), p. 55.
A13: U.S. food and beverage revenue per patron, 2025 | B13: 8.57 | F13: $ | G13: AMC Entertainment Holdings, Form 10-K for fiscal 2025 (filed 2026-02-23), p. 55.
A14: U.S. average ticket price change, 2025 | B14: 0.046 | F14: % | G14: AMC Entertainment Holdings, Form 10-K for fiscal 2025 (filed 2026-02-23), p. 55. Reference for the price growth assumption.
A15: U.S. food and beverage per patron change, 2025 | B15: 0.033 | F15: % | G15: AMC Entertainment Holdings, Form 10-K for fiscal 2025 (filed 2026-02-23), p. 55. Reference for the F&B growth assumption.
A16: U.S. attendance change, 2025 | B16: -0.007 | F16: % | G16: AMC Entertainment Holdings, Form 10-K for fiscal 2025 (filed 2026-02-23), p. 55 (156.9 million to 155.8 million patrons). Reference for the attendance trend.
A17: Discount rate AMC applied to U.S. theatre cash flows in impairment testing, Dec 31, 2025 | B17: 0.095 | F17: % | G17: AMC Entertainment Holdings, Form 10-K for fiscal 2025 (filed 2026-02-23), p. 46, Critical Accounting Estimates.
A18: Federal net operating loss carryforwards | B18: 1780.1 | F18: $ millions | G18: AMC Entertainment Holdings, Form 10-K for fiscal 2025 (filed 2026-02-23), p. 121, Note 9 Income Taxes. A valuation allowance is held against U.S. deferred tax assets (p. 119).
... A25: Typical initial non-cancellable JRSA term | B25: 10 | F25: years | G25: IMAX Corporation, Form 10-K for fiscal 2025 (filed 2026-02-25), p. 42. Sets the 10-year model horizon.
A27: B. Derived from public figures
A28: Item | B28: Value | F28: Unit | G28: Formula
A29: U.S. average ticket price, 2025 | B29: =Inputs!$B$7*1000/Inputs!$B$8 -> 12.784802 | F29: $ | G29: Admissions revenue / attendance.
A30: U.S. attendance per average screen, 2025 | B30: =Inputs!$B$8*1000/Inputs!$B$9 -> 22078.787 | F30: patrons | G30: Attendance / average screens.
A31: U.S. operating expense per average screen, 2025 | B31: =Inputs!$B$10*1000000/Inputs!$B$9 -> 188054.41 | F31: $ | G31: Operating expense / average screens.
A32: IMAX rentals as % of JRSA box office, 2025 | B32: =(Inputs!$B$19/1000)/Inputs!$B$20 -> 0.14676544 | F32: % | G32: Rentals / JRSA box office. A blended effective rate across traditional and hybrid JRSAs.
A33: IMAX revenue per new system installed, 2025 | B33: =Inputs!$B$21*1000/Inputs!$B$22 -> 891257.14 | F33: $ | G33: Revenue on new systems / systems installed. Mix of sales and hybrid deals.
A34: IMAX box office per screen vs. average domestic screen | B34: =Inputs!$B$23/Inputs!$B$24 -> 5.2 | F34: x | G34: Box office share / screen share.
A36: C. Assumptions (no public figure)
A37: Item | B37: Value | F37: Unit | G37: Rationale
A38: Attendance of the screen chosen for conversion vs. average U.S. screen | B38: 1.25 | F38: x | G38: Chains convert their largest, busiest auditoriums. No public figure.
A39: Share of premium tickets sold without the premium surcharge | B39: 0.15 | F39: % | G39: A-List subscribers can book IMAX and Dolby Cinema at no extra cost (AMC 10-K, p. 8). The share is assumed.
A40: Premium projection and sound system per screen | B40: =Inputs!$B$33 -> 891257.14 | F40: $ | G40: Proxy: IMAX's average revenue per new system installed in 2025 (section B). Applied in every scenario whatever the deal type; under a traditional JRSA, IMAX carries most of this cost, so the downside (blended JRSA share plus full equipment cost) is conservative.
A41: Auditorium construction per screen (screen wall, sound, seating, structure) | B41: 500000 | F41: $ | G41: No per-screen figure in the AMC or IMAX filings. Assumed.
A42: Conversion cost estimate per screen | B42: =Inputs!$B$40+Inputs!$B$41 -> 1391257.1 | F42: $ | G42: Equipment + construction. Scenarios scale this (section D).
A43: Weeks the screen is closed for conversion | B43: 8 | F43: weeks | G43: Assumed.
A44: Extra operating cost of a premium screen, % of average screen operating expense | B44: 0.15 | F44: % | G44: Annual maintenance fee (IMAX 10-K, p. 10, amount not disclosed), extra power and seat upkeep. Assumed.
A45: Ticket price growth per year | B45: 0.03 | F45: % | G45: Below the 4.6% U.S. increase in 2025 (section A), held at a long-run rate. Applies to standard and premium prices.
A46: Food and beverage per patron growth per year | B46: 0.03 | F46: % | G46: Close to the 3.3% U.S. increase in 2025 (section A).
A47: Operating cost inflation per year | B47: 0.03 | F47: % | G47: Assumed.
A48: Attendance trend per year | B48: 0 | F48: % | G48: U.S. attendance fell 0.7% in 2025 (section A); held flat.
A49: Cash tax rate on incremental profit | B49: 0 | F49: % | G49: AMC's federal NOLs (section A) shelter profit over the 10-year window. Raise to test a taxpaying owner; years with a tax loss are assumed to offset other taxable income.
...

Sheet Model
A1: Model: 10-year cash flows per converted screen
A2: ="Scenario shown: "&Inputs!$C$3&" (change on Inputs!B3)" -> Scenario shown: Base (change on Inputs!B3)
A3: Rows 5-10 do not depend on the scenario; the Scenarios and Sensitivity sheets reuse them.
A4: Year | C4: 0 | D4: =C4+1 -> 1 | E4: =D4+1 -> 2 | F4: =E4+1 -> 3 | G4: =F4+1 -> 4 | H4: =G4+1 -> 5 | I4: =H4+1 -> 6 | J4: =I4+1 -> 7 | K4: =J4+1 -> 8 | ... M4: =L4+1 -> 10
A5: Discount factor | C5: =1/(1+Inputs!$B$52)^C$4 -> 1 | D5: =1/(1+Inputs!$B$52)^D$4 -> 0.91324201 | E5: =1/(1+Inputs!$B$52)^E$4 -> 0.83401097 | F5: =1/(1+Inputs!$B$52)^F$4 -> 0.76165385 | G5: =1/(1+Inputs!$B$52)^G$4 -> 0.69557429 | H5: =1/(1+Inputs!$B$52)^H$4 -> 0.63522767 | I5: =1/(1+Inputs!$B$52)^I$4 -> 0.58011659 | J5: =1/(1+Inputs!$B$52)^J$4 -> 0.52978684 | ... M5: =1/(1+Inputs!$B$52)^M$4 -> 0.40351419
A6: Price index | D6: =(1+Inputs!$B$45)^(D$4-1) -> 1 | E6: =(1+Inputs!$B$45)^(E$4-1) -> 1.03 | F6: =(1+Inputs!$B$45)^(F$4-1) -> 1.0609 | G6: =(1+Inputs!$B$45)^(G$4-1) -> 1.092727 | H6: =(1+Inputs!$B$45)^(H$4-1) -> 1.1255088 | I6: =(1+Inputs!$B$45)^(I$4-1) -> 1.1592741 | J6: =(1+Inputs!$B$45)^(J$4-1) -> 1.1940523 | K6: =(1+Inputs!$B$45)^(K$4-1) -> 1.2298739 | ... M6: =(1+Inputs!$B$45)^(M$4-1) -> 1.3047732
A7: Attendance on the screen before conversion | B7: patrons | D7: =Inputs!$B$30*Inputs!$B$38*(1+Inputs!$B$48)^(D$4-1) -> 27598.484 | E7: =Inputs!$B$30*Inputs!$B$38*(1+Inputs!$B$48)^(E$4-1) -> 27598.484 | F7: =Inputs!$B$30*Inputs!$B$38*(1+Inputs!$B$48)^(F$4-1) -> 27598.484 | G7: =Inputs!$B$30*Inputs!$B$38*(1+Inputs!$B$48)^(G$4-1) -> 27598.484 | H7: =Inputs!$B$30*Inputs!$B$38*(1+Inputs!$B$48)^(H$4-1) -> 27598.484 | I7: =Inputs!$B$30*Inputs!$B$38*(1+Inputs!$B$48)^(I$4-1) -> 27598.484 | J7: =Inputs!$B$30*Inputs!$B$38*(1+Inputs!$B$48)^(J$4-1) -> 27598.484 | K7: =Inputs!$B$30*Inputs!$B$38*(1+Inputs!$B$48)^(K$4-1) -> 27598.484 | ... M7: =Inputs!$B$30*Inputs!$B$38*(1+Inputs!$B$48)^(M$4-1) -> 27598.484
A8: Standard ticket price | B8: $ | D8: =Inputs!$B$29*D6 -> 12.784802 | E8: =Inputs!$B$29*E6 -> 13.168346 | F8: =Inputs!$B$29*F6 -> 13.563396 | G8: =Inputs!$B$29*G6 -> 13.970298 | H8: =Inputs!$B$29*H6 -> 14.389407 | I8: =Inputs!$B$29*I6 -> 14.82109 | J8: =Inputs!$B$29*J6 -> 15.265722 | K8: =Inputs!$B$29*K6 -> 15.723694 | ... M8: =Inputs!$B$29*M6 -> 16.681267
A9: Food and beverage revenue per patron | B9: $ | D9: =Inputs!$B$13*(1+Inputs!$B$46)^(D$4-1) -> 8.57 | E9: =Inputs!$B$13*(1+Inputs!$B$46)^(E$4-1) -> 8.8271 | F9: =Inputs!$B$13*(1+Inputs!$B$46)^(F$4-1) -> 9.091913 | G9: =Inputs!$B$13*(1+Inputs!$B$46)^(G$4-1) -> 9.3646704 | H9: =Inputs!$B$13*(1+Inputs!$B$46)^(H$4-1) -> 9.6456105 | I9: =Inputs!$B$13*(1+Inputs!$B$46)^(I$4-1) -> 9.9349788 | J9: =Inputs!$B$13*(1+Inputs!$B$46)^(J$4-1) -> 10.233028 | K9: =Inputs!$B$13*(1+Inputs!$B$46)^(K$4-1) -> 10.540019 | ... M9: =Inputs!$B$13*(1+Inputs!$B$46)^(M$4-1) -> 11.181906
A10: Extra operating cost of the premium screen | B10: $ | D10: =Inputs!$B$31*Inputs!$B$44*(1+Inputs!$B$47)^(D$4-1) -> 28208.162 | E10: =Inputs!$B$31*Inputs!$B$44*(1+Inputs!$B$47)^(E$4-1) -> 29054.407 | F10: =Inputs!$B$31*Inputs!$B$44*(1+Inputs!$B$47)^(F$4-1) -> 29926.039 | G10: =Inputs!$B$31*Inputs!$B$44*(1+Inputs!$B$47)^(G$4-1) -> 30823.82 | H10: =Inputs!$B$31*Inputs!$B$44*(1+Inputs!$B$47)^(H$4-1) -> 31748.535 | I10: =Inputs!$B$31*Inputs!$B$44*(1+Inputs!$B$47)^(I$4-1) -> 32700.991 | J10: =Inputs!$B$31*Inputs!$B$44*(1+Inputs!$B$47)^(J$4-1) -> 33682.021 | K10: =Inputs!$B$31*Inputs!$B$44*(1+Inputs!$B$47)^(K$4-1) -> 34692.481 | ... M10: =Inputs!$B$31*Inputs!$B$44*(1+Inputs!$B$47)^(M$4-1) -> 36805.253
A12: Scenario drivers
A13: Attendance on the converted screen | B13: patrons | D13: =D7*(1+Inputs!$E$56) -> 55196.968 | E13: =E7*(1+Inputs!$E$56) -> 55196.968 | F13: =F7*(1+Inputs!$E$56) -> 55196.968 | G13: =G7*(1+Inputs!$E$56) -> 55196.968 | H13: =H7*(1+Inputs!$E$56) -> 55196.968 | I13: =I7*(1+Inputs!$E$56) -> 55196.968 | J13: =J7*(1+Inputs!$E$56) -> 55196.968 | K13: =K7*(1+Inputs!$E$56) -> 55196.968 | ... M13: =M7*(1+Inputs!$E$56) -> 55196.968
A14: Extra attendance moved from other screens | B14: patrons | D14: =D7*Inputs!$E$56*Inputs!$E$58 -> 13799.242 | E14: =E7*Inputs!$E$56*Inputs!$E$58 -> 13799.242 | F14: =F7*Inputs!$E$56*Inputs!$E$58 -> 13799.242 | G14: =G7*Inputs!$E$56*Inputs!$E$58 -> 13799.242 | H14: =H7*Inputs!$E$56*Inputs!$E$58 -> 13799.242 | I14: =I7*Inputs!$E$56*Inputs!$E$58 -> 13799.242 | J14: =J7*Inputs!$E$56*Inputs!$E$58 -> 13799.242 | K14: =K7*Inputs!$E$56*Inputs!$E$58 -> 13799.242 | ... M14: =M7*Inputs!$E$56*Inputs!$E$58 -> 13799.242
A15: Net new attendance to the theatre | B15: patrons | D15: =D7*Inputs!$E$56*(1-Inputs!$E$58) -> 13799.242 | E15: =E7*Inputs!$E$56*(1-Inputs!$E$58) -> 13799.242 | F15: =F7*Inputs!$E$56*(1-Inputs!$E$58) -> 13799.242 | G15: =G7*Inputs!$E$56*(1-Inputs!$E$58) -> 13799.242 | H15: =H7*Inputs!$E$56*(1-Inputs!$E$58) -> 13799.242 | I15: =I7*Inputs!$E$56*(1-Inputs!$E$58) -> 13799.242 | J15: =J7*Inputs!$E$56*(1-Inputs!$E$58) -> 13799.242 | K15: =K7*Inputs!$E$56*(1-Inputs!$E$58) -> 13799.242 | ... M15: =M7*Inputs!$E$56*(1-Inputs!$E$58) -> 13799.242
A16: Premium ticket price, net of tickets sold without surcharge | B16: $ | D16: =(Inputs!$B$29+Inputs!$E$57*(1-Inputs!$B$39))*D6 -> 17.034802 | E16: =(Inputs!$B$29+Inputs!$E$57*(1-Inputs!$B$39))*E6 -> 17.545846 | F16: =(Inputs!$B$29+Inputs!$E$57*(1-Inputs!$B$39))*F6 -> 18.072221 | G16: =(Inputs!$B$29+Inputs!$E$57*(1-Inputs!$B$39))*G6 -> 18.614388 | H16: =(Inputs!$B$29+Inputs!$E$57*(1-Inputs!$B$39))*H6 -> 19.17282 | I16: =(Inputs!$B$29+Inputs!$E$57*(1-Inputs!$B$39))*I6 -> 19.748004 | J16: =(Inputs!$B$29+Inputs!$E$57*(1-Inputs!$B$39))*J6 -> 20.340444 | K16: =(Inputs!$B$29+Inputs!$E$57*(1-Inputs!$B$39))*K6 -> 20.950658 | ... M16: =(Inputs!$B$29+Inputs!$E$57*(1-Inputs!$B$39))*M6 -> 22.226553
A18: Incremental revenue and costs
A19: Admissions on the converted screen | B19: $ | D19: =D13*D16 -> 940269.41 | E19: =E13*E16 -> 968477.5 | F19: =F13*F16 -> 997531.82 | G19: =G13*G16 -> 1027457.8 | H19: =H13*H16 -> 1058281.5 | I19: =I13*I16 -> 1090030 | J19: =J13*J16 -> 1122730.9 | K19: =K13*K16 -> 1156412.8 | ... M19: =M13*M16 -> 1226838.3
A20: Less: admissions the screen earned as a standard screen | B20: $ | D20: =-D7*D8 -> -352841.15 | E20: =-E7*E8 -> -363426.39 | F20: =-F7*F8 -> -374329.18 | G20: =-G7*G8 -> -385559.05 | H20: =-H7*H8 -> -397125.82 | I20: =-I7*I8 -> -409039.6 | J20: =-J7*J8 -> -421310.79 | K20: =-K7*K8 -> -433950.11 | ... M20: =-M7*M8 -> -460377.67
A21: Less: admissions lost by other screens | B21: $ | D21: =-D14*D8 -> -176420.58 | E21: =-E14*E8 -> -181713.19 | F21: =-F14*F8 -> -187164.59 | G21: =-G14*G8 -> -192779.53 | H21: =-H14*H8 -> -198562.91 | I21: =-I14*I8 -> -204519.8 | J21: =-J14*J8 -> -210655.39 | K21: =-K14*K8 -> -216975.05 | ... M21: =-M14*M8 -> -230188.84
A22: Incremental admissions revenue | B22: $ | D22: =SUM(D19:D21) -> 411007.69 | E22: =SUM(E19:E21) -> 423337.92 | F22: =SUM(F19:F21) -> 436038.06 | G22: =SUM(G19:G21) -> 449119.2 | H22: =SUM(H19:H21) -> 462592.77 | I22: =SUM(I19:I21) -> 476470.56 | J22: =SUM(J19:J21) -> 490764.67 | K22: =SUM(K19:K21) -> 505487.61 | ... M22: =SUM(M19:M21) -> 536271.81
A23: Film exhibition cost on incremental admissions | B23: $ | D23: =-Inputs!$B$11*D22 -> -210435.94 | E23: =-Inputs!$B$11*E22 -> -216749.01 | F23: =-Inputs!$B$11*F22 -> -223251.48 | G23: =-Inputs!$B$11*G22 -> -229949.03 | H23: =-Inputs!$B$11*H22 -> -236847.5 | I23: =-Inputs!$B$11*I22 -> -243952.92 | J23: =-Inputs!$B$11*J22 -> -251271.51 | K23: =-Inputs!$B$11*K22 -> -258809.66 | ... M23: =-Inputs!$B$11*M22 -> -274571.17
A24: Format partner share of converted screen box office | B24: $ | D24: =-Inputs!$E$59*D19 -> -94026.941 | E24: =-Inputs!$E$59*E19 -> -96847.75 | F24: =-Inputs!$E$59*F19 -> -99753.182 | G24: =-Inputs!$E$59*G19 -> -102745.78 | H24: =-Inputs!$E$59*H19 -> -105828.15 | I24: =-Inputs!$E$59*I19 -> -109003 | J24: =-Inputs!$E$59*J19 -> -112273.09 | K24: =-Inputs!$E$59*K19 -> -115641.28 | ... M24: =-Inputs!$E$59*M19 -> -122683.83
A25: Incremental food and beverage revenue | B25: $ | D25: =D15*D9 -> 118259.5 | E25: =E15*E9 -> 121807.29 | F25: =F15*F9 -> 125461.51 | G25: =G15*G9 -> 129225.35 | H25: =H15*H9 -> 133102.11 | I25: =I15*I9 -> 137095.18 | J25: =J15*J9 -> 141208.03 | K25: =K15*K9 -> 145444.27 | ... M25: =M15*M9 -> 154301.83
A26: Food and beverage cost | B26: $ | D26: =-Inputs!$B$12*D25 -> -21404.97 | E26: =-Inputs!$B$12*E25 -> -22047.119 | F26: =-Inputs!$B$12*F25 -> -22708.533 | G26: =-Inputs!$B$12*G25 -> -23389.789 | H26: =-Inputs!$B$12*H25 -> -24091.482 | I26: =-Inputs!$B$12*I25 -> -24814.227 | J26: =-Inputs!$B$12*J25 -> -25558.654 | K26: =-Inputs!$B$12*K25 -> -26325.413 | ... M26: =-Inputs!$B$12*M25 -> -27928.631
A27: Extra operating cost | B27: $ | D27: =-D10 -> -28208.162 | E27: =-E10 -> -29054.407 | F27: =-F10 -> -29926.039 | G27: =-G10 -> -30823.82 | H27: =-H10 -> -31748.535 | I27: =-I10 -> -32700.991 | J27: =-J10 -> -33682.021 | K27: =-K10 -> -34692.481 | ... M27: =-M10 -> -36805.253
A28: Incremental EBITDA | B28: $ | D28: =D22+D23+D24+D25+D26+D27 -> 175191.18 | E28: =E22+E23+E24+E25+E26+E27 -> 180446.92 | F28: =F22+F23+F24+F25+F26+F27 -> 185860.32 | G28: =G22+G23+G24+G25+G26+G27 -> 191436.13 | H28: =H22+H23+H24+H25+H26+H27 -> 197179.22 | I28: =I22+I23+I24+I25+I26+I27 -> 203094.59 | J28: =J22+J23+J24+J25+J26+J27 -> 209187.43 | K28: =K22+K23+K24+K25+K26+K27 -> 215463.05 | ... M28: =M22+M23+M24+M25+M26+M27 -> 228584.75
A30: Depreciation (for tax only) | B30: $ | D30: =IF(D$4<=Inputs!$B$50,Inputs!$E$61/Inputs!$B$50,0) -> 139125.71 | E30: =IF(E$4<=Inputs!$B$50,Inputs!$E$61/Inputs!$B$50,0) -> 139125.71 | F30: =IF(F$4<=Inputs!$B$50,Inputs!$E$61/Inputs!$B$50,0) -> 139125.71 | G30: =IF(G$4<=Inputs!$B$50,Inputs!$E$61/Inputs!$B$50,0) -> 139125.71 | H30: =IF(H$4<=Inputs!$B$50,Inputs!$E$61/Inputs!$B$50,0) -> 139125.71 | I30: =IF(I$4<=Inputs!$B$50,Inputs!$E$61/Inputs!$B$50,0) -> 139125.71 | J30: =IF(J$4<=Inputs!$B$50,Inputs!$E$61/Inputs!$B$50,0) -> 139125.71 | K30: =IF(K$4<=Inputs!$B$50,Inputs!$E$61/Inputs!$B$50,0) -> 139125.71 | ... M30: =IF(M$4<=Inputs!$B$50,Inputs!$E$61/Inputs!$B$50,0) -> 139125.71
A31: Cash tax | B31: $ | D31: =-Inputs!$B$49*(D28-D30) -> 0 | E31: =-Inputs!$B$49*(E28-E30) -> 0 | F31: =-Inputs!$B$49*(F28-F30) -> 0 | G31: =-Inputs!$B$49*(G28-G30) -> 0 | H31: =-Inputs!$B$49*(H28-H30) -> 0 | I31: =-Inputs!$B$49*(I28-I30) -> 0 | J31: =-Inputs!$B$49*(J28-J30) -> 0 | K31: =-Inputs!$B$49*(K28-K30) -> 0 | ... M31: =-Inputs!$B$49*(M28-M30) -> 0
A32: Conversion cost | B32: $ | C32: =-Inputs!$E$61 -> -1391257.1
A33: Contribution lost while the screen is closed | B33: $ | C33: =-Inputs!$B$43/52*D7*(D8*(1-Inputs!$B$11)+D9*(1-Inputs!$B$12)) -> -56291.623
A34: Residual value | B34: $ | D34: =IF(D$4=$M$4,Inputs!$B$51*Inputs!$E$61,0) -> 0 | E34: =IF(E$4=$M$4,Inputs!$B$51*Inputs!$E$61,0) -> 0 | F34: =IF(F$4=$M$4,Inputs!$B$51*Inputs!$E$61,0) -> 0 | G34: =IF(G$4=$M$4,Inputs!$B$51*Inputs!$E$61,0) -> 0 | H34: =IF(H$4=$M$4,Inputs!$B$51*Inputs!$E$61,0) -> 0 | I34: =IF(I$4=$M$4,Inputs!$B$51*Inputs!$E$61,0) -> 0 | J34: =IF(J$4=$M$4,Inputs!$B$51*Inputs!$E$61,0) -> 0 | K34: =IF(K$4=$M$4,Inputs!$B$51*Inputs!$E$61,0) -> 0 | ... M34: =IF(M$4=$M$4,Inputs!$B$51*Inputs!$E$61,0) -> 0
A35: Net cash flow | B35: $ | C35: =C32+C33 -> -1447548.8 | D35: =D28+D31+D34 -> 175191.18 | E35: =E28+E31+E34 -> 180446.92 | F35: =F28+F31+F34 -> 185860.32 | G35: =G28+G31+G34 -> 191436.13 | H35: =H28+H31+H34 -> 197179.22 | I35: =I28+I31+I34 -> 203094.59 | J35: =J28+J31+J34 -> 209187.43 | K35: =K28+K31+K34 -> 215463.05 | ... M35: =M28+M31+M34 -> 228584.75
A36: Cumulative cash flow | B36: $ | C36: =C35 -> -1447548.8 | D36: =C36+D35 -> -1272357.6 | E36: =D36+E35 -> -1091910.7 | F36: =E36+F35 -> -906050.34 | G36: =F36+G35 -> -714614.21 | H36: =G36+H35 -> -517434.99 | I36: =H36+I35 -> -314340.4 | J36: =I36+J35 -> -105152.97 | K36: =J36+K35 -> 110310.09 | ... M36: =L36+M35 -> 560821.79
A37: Discounted cash flow | B37: $ | C37: =C35*C5 -> -1447548.8 | D37: =D35*D5 -> 159991.95 | E37: =E35*E5 -> 150494.71 | F37: =F35*F5 -> 141561.23 | G37: =G35*G5 -> 133158.05 | H37: =H35*H5 -> 125253.69 | I37: =I35*I5 -> 117818.54 | J37: =J35*J5 -> 110824.75 | ... M37: =M35*M5 -> 92237.191
A39: Net present value (NPV) | C39: =SUM(C37:M37) -> -213904.55
A40: Internal rate of return (IRR) | C40: =IFERROR(IRR(C35:M35,0.05),"Not meaningful") -> 0.061365528
A41: Payback period | C41: =IF(M36<0,"Not within 10 years",COUNTIF(D36:M36,"<0")-INDEX(C36:M36,COUNTIF(D36:M36,"<0")+1)/INDEX(D35:M35,COUNTIF(D36:M36,"<0")+1)) -> 7.4880325
A42: 10-year cumulative cash flow | C42: =M36 -> 560821.79
A43: Check: converted screen box office vs. AMC average U.S. screen, year 1 | C43: =D19/(Inputs!$B$30*Inputs!$B$29) -> 3.3310649 | D43: ="Compare: IMAX screens average "&TEXT(Inputs!$B$34,"0.0")&"x the industry average domestic screen (Inputs, section B)" -> Compare: IMAX screens average 5.2x the industry average domestic screen (Inputs, section B)

Sheet Scenarios
A1: Scenarios: base, upside and downside
A2: Each scenario is calculated in full below, so all three show at once. Drivers that do not change by scenario come from Model rows 5-10.
A4: Lever | B4: Base | C4: Upside | D4: Downside
A5: Attendance uplift | B5: =Inputs!$B$56 -> 1 | C5: =Inputs!$C$56 -> 1.5 | D5: =Inputs!$D$56 -> 0.5
A6: Premium surcharge, year 1 | B6: =Inputs!$B$57 -> 5 | C6: =Inputs!$C$57 -> 6.5 | D6: =Inputs!$D$57 -> 3.5
A7: Cannibalization share | B7: =Inputs!$B$58 -> 0.5 | C7: =Inputs!$C$58 -> 0.35 | D7: =Inputs!$D$58 -> 0.65
A8: Format partner share | B8: =Inputs!$B$59 -> 0.1 | C8: =Inputs!$C$59 -> 0.075 | D8: =Inputs!$D$59 -> 0.14676544
A9: Conversion cost vs. estimate | B9: =Inputs!$B$60 -> 1 | C9: =Inputs!$C$60 -> 0.9 | D9: =Inputs!$D$60 -> 1.25
A10: Conversion cost per screen | B10: =Inputs!$B$61 -> 1391257.1 | C10: =Inputs!$C$61 -> 1252131.4 | D10: =Inputs!$D$61 -> 1739071.4
A12: Result | B12: Base | C12: Upside | D12: Downside
A13: Net present value (NPV) | B13: =SUMPRODUCT(Model!$C$5:$M$5,C29:M29) -> -213904.55 | C13: =SUMPRODUCT(Model!$C$5:$M$5,C41:M41) -> 1647821.5 | D13: =SUMPRODUCT(Model!$C$5:$M$5,C53:M53) -> -1794151.4
A14: Internal rate of return (IRR) | B14: =IFERROR(IRR(C29:M29,0.05),"Not meaningful") -> 0.061365528 | C14: =IFERROR(IRR(C41:M41,0.05),"Not meaningful") -> 0.32500643 | D14: =IFERROR(IRR(C53:M53,0.05),"Not meaningful") -> Not meaningful
A15: Payback period | B15: =IF(M30<0,"Not within 10 years",COUNTIF(D30:M30,"<0")-INDEX(C30:M30,COUNTIF(D30:M30,"<0")+1)/INDEX(D29:M29,COUNTIF(D30:M30,"<0")+1)) -> 7.4880325 | C15: =IF(M42<0,"Not within 10 years",COUNTIF(D42:M42,"<0")-INDEX(C42:M42,COUNTIF(D42:M42,"<0")+1)/INDEX(D41:M41,COUNTIF(D42:M42,"<0")+1)) -> 3.0235484 | D15: =IF(M54<0,"Not within 10 years",COUNTIF(D54:M54,"<0")-INDEX(C54:M54,COUNTIF(D54:M54,"<0")+1)/INDEX(D53:M53,COUNTIF(D54:M54,"<0")+1)) -> Not within 10 years
A16: 10-year cumulative cash flow | B16: =M30 -> 560821.79 | C16: =M42 -> 3504337.7 | D16: =M54 -> -1793390.4
A17: Incremental EBITDA, year 1 | B17: =D26 -> 175191.18 | C17: =D38 -> 419819.56 | D17: =D50 -> 172.07374
A19: Check: Model sheet NPV equals this sheet for the scenario shown there | B19: =IF(ABS(Model!$C$39-INDEX(B13:D13,Inputs!$B$3))<0.5,"OK","CHECK") -> OK
A21: Base case cash flows | B21: Year | C21: =Model!C$4 -> 0 | D21: =Model!D$4 -> 1 | E21: =Model!E$4 -> 2 | F21: =Model!F$4 -> 3 | G21: =Model!G$4 -> 4 | H21: =Model!H$4 -> 5 | I21: =Model!I$4 -> 6 | J21: =Model!J$4 -> 7 | ... M21: =Model!M$4 -> 10
A22: Incremental admissions revenue | D22: =Model!D$7*(1+$B$5)*((Inputs!$B$29+$B$6*(1-Inputs!$B$39))*Model!D$6)-Model!D$7*Model!D$8-Model!D$7*$B$5*$B$7*Model!D$8 -> 411007.69 | E22: =Model!E$7*(1+$B$5)*((Inputs!$B$29+$B$6*(1-Inputs!$B$39))*Model!E$6)-Model!E$7*Model!E$8-Model!E$7*$B$5*$B$7*Model!E$8 -> 423337.92 | F22: =Model!F$7*(1+$B$5)*((Inputs!$B$29+$B$6*(1-Inputs!$B$39))*Model!F$6)-Model!F$7*Model!F$8-Model!F$7*$B$5*$B$7*Model!F$8 -> 436038.06 | G22: =Model!G$7*(1+$B$5)*((Inputs!$B$29+$B$6*(1-Inputs!$B$39))*Model!G$6)-Model!G$7*Model!G$8-Model!G$7*$B$5*$B$7*Model!G$8 -> 449119.2 | H22: =Model!H$7*(1+$B$5)*((Inputs!$B$29+$B$6*(1-Inputs!$B$39))*Model!H$6)-Model!H$7*Model!H$8-Model!H$7*$B$5*$B$7*Model!H$8 -> 462592.77 | I22: =Model!I$7*(1+$B$5)*((Inputs!$B$29+$B$6*(1-Inputs!$B$39))*Model!I$6)-Model!I$7*Model!I$8-Model!I$7*$B$5*$B$7*Model!I$8 -> 476470.56 | J22: =Model!J$7*(1+$B$5)*((Inputs!$B$29+$B$6*(1-Inputs!$B$39))*Model!J$6)-Model!J$7*Model!J$8-Model!J$7*$B$5*$B$7*Model!J$8 -> 490764.67 | K22: =Model!K$7*(1+$B$5)*((Inputs!$B$29+$B$6*(1-Inputs!$B$39))*Model!K$6)-Model!K$7*Model!K$8-Model!K$7*$B$5*$B$7*Model!K$8 -> 505487.61 | ... M22: =Model!M$7*(1+$B$5)*((Inputs!$B$29+$B$6*(1-Inputs!$B$39))*Model!M$6)-Model!M$7*Model!M$8-Model!M$7*$B$5*$B$7*Model!M$8 -> 536271.81
A23: Film cost and format partner share | D23: =-Inputs!$B$11*D22-$B$8*Model!D$7*(1+$B$5)*((Inputs!$B$29+$B$6*(1-Inputs!$B$39))*Model!D$6) -> -304462.88 | E23: =-Inputs!$B$11*E22-$B$8*Model!E$7*(1+$B$5)*((Inputs!$B$29+$B$6*(1-Inputs!$B$39))*Model!E$6) -> -313596.76 | F23: =-Inputs!$B$11*F22-$B$8*Model!F$7*(1+$B$5)*((Inputs!$B$29+$B$6*(1-Inputs!$B$39))*Model!F$6) -> -323004.67 | G23: =-Inputs!$B$11*G22-$B$8*Model!G$7*(1+$B$5)*((Inputs!$B$29+$B$6*(1-Inputs!$B$39))*Model!G$6) -> -332694.81 | H23: =-Inputs!$B$11*H22-$B$8*Model!H$7*(1+$B$5)*((Inputs!$B$29+$B$6*(1-Inputs!$B$39))*Model!H$6) -> -342675.65 | I23: =-Inputs!$B$11*I22-$B$8*Model!I$7*(1+$B$5)*((Inputs!$B$29+$B$6*(1-Inputs!$B$39))*Model!I$6) -> -352955.92 | J23: =-Inputs!$B$11*J22-$B$8*Model!J$7*(1+$B$5)*((Inputs!$B$29+$B$6*(1-Inputs!$B$39))*Model!J$6) -> -363544.6 | K23: =-Inputs!$B$11*K22-$B$8*Model!K$7*(1+$B$5)*((Inputs!$B$29+$B$6*(1-Inputs!$B$39))*Model!K$6) -> -374450.94 | ... M23: =-Inputs!$B$11*M22-$B$8*Model!M$7*(1+$B$5)*((Inputs!$B$29+$B$6*(1-Inputs!$B$39))*Model!M$6) -> -397255
A24: Food and beverage contribution | D24: =Model!D$7*$B$5*(1-$B$7)*Model!D$9*(1-Inputs!$B$12) -> 96854.533 | E24: =Model!E$7*$B$5*(1-$B$7)*Model!E$9*(1-Inputs!$B$12) -> 99760.169 | F24: =Model!F$7*$B$5*(1-$B$7)*Model!F$9*(1-Inputs!$B$12) -> 102752.97 | G24: =Model!G$7*$B$5*(1-$B$7)*Model!G$9*(1-Inputs!$B$12) -> 105835.56 | H24: =Model!H$7*$B$5*(1-$B$7)*Model!H$9*(1-Inputs!$B$12) -> 109010.63 | I24: =Model!I$7*$B$5*(1-$B$7)*Model!I$9*(1-Inputs!$B$12) -> 112280.95 | J24: =Model!J$7*$B$5*(1-$B$7)*Model!J$9*(1-Inputs!$B$12) -> 115649.38 | K24: =Model!K$7*$B$5*(1-$B$7)*Model!K$9*(1-Inputs!$B$12) -> 119118.86 | ... M24: =Model!M$7*$B$5*(1-$B$7)*Model!M$9*(1-Inputs!$B$12) -> 126373.2
A25: Extra operating cost | D25: =-Model!D$10 -> -28208.162 | E25: =-Model!E$10 -> -29054.407 | F25: =-Model!F$10 -> -29926.039 | G25: =-Model!G$10 -> -30823.82 | H25: =-Model!H$10 -> -31748.535 | I25: =-Model!I$10 -> -32700.991 | J25: =-Model!J$10 -> -33682.021 | K25: =-Model!K$10 -> -34692.481 | ... M25: =-Model!M$10 -> -36805.253
A26: Incremental EBITDA | D26: =SUM(D22:D25) -> 175191.18 | E26: =SUM(E22:E25) -> 180446.92 | F26: =SUM(F22:F25) -> 185860.32 | G26: =SUM(G22:G25) -> 191436.13 | H26: =SUM(H22:H25) -> 197179.22 | I26: =SUM(I22:I25) -> 203094.59 | J26: =SUM(J22:J25) -> 209187.43 | K26: =SUM(K22:K25) -> 215463.05 | ... M26: =SUM(M22:M25) -> 228584.75
A27: Cash tax | D27: =-Inputs!$B$49*(D26-IF(D$21<=Inputs!$B$50,$B$10/Inputs!$B$50,0)) -> 0 | E27: =-Inputs!$B$49*(E26-IF(E$21<=Inputs!$B$50,$B$10/Inputs!$B$50,0)) -> 0 | F27: =-Inputs!$B$49*(F26-IF(F$21<=Inputs!$B$50,$B$10/Inputs!$B$50,0)) -> 0 | G27: =-Inputs!$B$49*(G26-IF(G$21<=Inputs!$B$50,$B$10/Inputs!$B$50,0)) -> 0 | H27: =-Inputs!$B$49*(H26-IF(H$21<=Inputs!$B$50,$B$10/Inputs!$B$50,0)) -> 0 | I27: =-Inputs!$B$49*(I26-IF(I$21<=Inputs!$B$50,$B$10/Inputs!$B$50,0)) -> 0 | J27: =-Inputs!$B$49*(J26-IF(J$21<=Inputs!$B$50,$B$10/Inputs!$B$50,0)) -> 0 | K27: =-Inputs!$B$49*(K26-IF(K$21<=Inputs!$B$50,$B$10/Inputs!$B$50,0)) -> 0 | ... M27: =-Inputs!$B$49*(M26-IF(M$21<=Inputs!$B$50,$B$10/Inputs!$B$50,0)) -> 0
A28: Conversion cost, closure and residual value | C28: =-$B$10-Inputs!$B$43/52*Model!$D$7*(Model!$D$8*(1-Inputs!$B$11)+Model!$D$9*(1-Inputs!$B$12)) -> -1447548.8 | D28: =IF(D$21=$M$21,Inputs!$B$51*$B$10,0) -> 0 | E28: =IF(E$21=$M$21,Inputs!$B$51*$B$10,0) -> 0 | F28: =IF(F$21=$M$21,Inputs!$B$51*$B$10,0) -> 0 | G28: =IF(G$21=$M$21,Inputs!$B$51*$B$10,0) -> 0 | H28: =IF(H$21=$M$21,Inputs!$B$51*$B$10,0) -> 0 | I28: =IF(I$21=$M$21,Inputs!$B$51*$B$10,0) -> 0 | J28: =IF(J$21=$M$21,Inputs!$B$51*$B$10,0) -> 0 | K28: =IF(K$21=$M$21,Inputs!$B$51*$B$10,0) -> 0 | ... M28: =IF(M$21=$M$21,Inputs!$B$51*$B$10,0) -> 0
A29: Net cash flow | C29: =C28 -> -1447548.8 | D29: =D26+D27+D28 -> 175191.18 | E29: =E26+E27+E28 -> 180446.92 | F29: =F26+F27+F28 -> 185860.32 | G29: =G26+G27+G28 -> 191436.13 | H29: =H26+H27+H28 -> 197179.22 | I29: =I26+I27+I28 -> 203094.59 | J29: =J26+J27+J28 -> 209187.43 | K29: =K26+K27+K28 -> 215463.05 | ... M29: =M26+M27+M28 -> 228584.75
A30: Cumulative cash flow | C30: =C29 -> -1447548.8 | D30: =C30+D29 -> -1272357.6 | E30: =D30+E29 -> -1091910.7 | F30: =E30+F29 -> -906050.34 | G30: =F30+G29 -> -714614.21 | H30: =G30+H29 -> -517434.99 | I30: =H30+I29 -> -314340.4 | J30: =I30+J29 -> -105152.97 | K30: =J30+K29 -> 110310.09 | ... M30: =L30+M29 -> 560821.79
A33: Upside case cash flows | B33: Year | C33: =Model!C$4 -> 0 | D33: =Model!D$4 -> 1 | E33: =Model!E$4 -> 2 | F33: =Model!F$4 -> 3 | G33: =Model!G$4 -> 4 | H33: =Model!H$4 -> 5 | I33: =Model!I$4 -> 6 | J33: =Model!J$4 -> 7 | ... M33: =Model!M$4 -> 10
A34: Incremental admissions revenue | D34: =Model!D$7*(1+$C$5)*((Inputs!$B$29+$C$6*(1-Inputs!$B$39))*Model!D$6)-Model!D$7*Model!D$8-Model!D$7*$C$5*$C$7*Model!D$8 -> 725224.18 | E34: =Model!E$7*(1+$C$5)*((Inputs!$B$29+$C$6*(1-Inputs!$B$39))*Model!E$6)-Model!E$7*Model!E$8-Model!E$7*$C$5*$C$7*Model!E$8 -> 746980.9 | F34: =Model!F$7*(1+$C$5)*((Inputs!$B$29+$C$6*(1-Inputs!$B$39))*Model!F$6)-Model!F$7*Model!F$8-Model!F$7*$C$5*$C$7*Model!F$8 -> 769390.33 | G34: =Model!G$7*(1+$C$5)*((Inputs!$B$29+$C$6*(1-Inputs!$B$39))*Model!G$6)-Model!G$7*Model!G$8-Model!G$7*$C$5*$C$7*Model!G$8 -> 792472.04 | H34: =Model!H$7*(1+$C$5)*((Inputs!$B$29+$C$6*(1-Inputs!$B$39))*Model!H$6)-Model!H$7*Model!H$8-Model!H$7*$C$5*$C$7*Model!H$8 -> 816246.2 | I34: =Model!I$7*(1+$C$5)*((Inputs!$B$29+$C$6*(1-Inputs!$B$39))*Model!I$6)-Model!I$7*Model!I$8-Model!I$7*$C$5*$C$7*Model!I$8 -> 840733.59 | J34: =Model!J$7*(1+$C$5)*((Inputs!$B$29+$C$6*(1-Inputs!$B$39))*Model!J$6)-Model!J$7*Model!J$8-Model!J$7*$C$5*$C$7*Model!J$8 -> 865955.6 | K34: =Model!K$7*(1+$C$5)*((Inputs!$B$29+$C$6*(1-Inputs!$B$39))*Model!K$6)-Model!K$7*Model!K$8-Model!K$7*$C$5*$C$7*Model!K$8 -> 891934.26 | ... M34: =Model!M$7*(1+$C$5)*((Inputs!$B$29+$C$6*(1-Inputs!$B$39))*Model!M$6)-Model!M$7*Model!M$8-Model!M$7*$C$5*$C$7*Model!M$8 -> 946253.06
A35: Film cost and format partner share | D35: =-Inputs!$B$11*D34-$C$8*Model!D$7*(1+$C$5)*((Inputs!$B$29+$C$6*(1-Inputs!$B$39))*Model!D$6) -> -466062.8 | E35: =-Inputs!$B$11*E34-$C$8*Model!E$7*(1+$C$5)*((Inputs!$B$29+$C$6*(1-Inputs!$B$39))*Model!E$6) -> -480044.68 | F35: =-Inputs!$B$11*F34-$C$8*Model!F$7*(1+$C$5)*((Inputs!$B$29+$C$6*(1-Inputs!$B$39))*Model!F$6) -> -494446.02 | G35: =-Inputs!$B$11*G34-$C$8*Model!G$7*(1+$C$5)*((Inputs!$B$29+$C$6*(1-Inputs!$B$39))*Model!G$6) -> -509279.4 | H35: =-Inputs!$B$11*H34-$C$8*Model!H$7*(1+$C$5)*((Inputs!$B$29+$C$6*(1-Inputs!$B$39))*Model!H$6) -> -524557.79 | I35: =-Inputs!$B$11*I34-$C$8*Model!I$7*(1+$C$5)*((Inputs!$B$29+$C$6*(1-Inputs!$B$39))*Model!I$6) -> -540294.52 | J35: =-Inputs!$B$11*J34-$C$8*Model!J$7*(1+$C$5)*((Inputs!$B$29+$C$6*(1-Inputs!$B$39))*Model!J$6) -> -556503.36 | K35: =-Inputs!$B$11*K34-$C$8*Model!K$7*(1+$C$5)*((Inputs!$B$29+$C$6*(1-Inputs!$B$39))*Model!K$6) -> -573198.46 | ... M35: =-Inputs!$B$11*M34-$C$8*Model!M$7*(1+$C$5)*((Inputs!$B$29+$C$6*(1-Inputs!$B$39))*Model!M$6) -> -608106.24
A36: Food and beverage contribution | D36: =Model!D$7*$C$5*(1-$C$7)*Model!D$9*(1-Inputs!$B$12) -> 188866.34 | E36: =Model!E$7*$C$5*(1-$C$7)*Model!E$9*(1-Inputs!$B$12) -> 194532.33 | F36: =Model!F$7*$C$5*(1-$C$7)*Model!F$9*(1-Inputs!$B$12) -> 200368.3 | G36: =Model!G$7*$C$5*(1-$C$7)*Model!G$9*(1-Inputs!$B$12) -> 206379.35 | H36: =Model!H$7*$C$5*(1-$C$7)*Model!H$9*(1-Inputs!$B$12) -> 212570.73 | I36: =Model!I$7*$C$5*(1-$C$7)*Model!I$9*(1-Inputs!$B$12) -> 218947.85 | J36: =Model!J$7*$C$5*(1-$C$7)*Model!J$9*(1-Inputs!$B$12) -> 225516.29 | K36: =Model!K$7*$C$5*(1-$C$7)*Model!K$9*(1-Inputs!$B$12) -> 232281.77 | ... M36: =Model!M$7*$C$5*(1-$C$7)*Model!M$9*(1-Inputs!$B$12) -> 246427.73
A37: Extra operating cost | D37: =-Model!D$10 -> -28208.162 | E37: =-Model!E$10 -> -29054.407 | F37: =-Model!F$10 -> -29926.039 | G37: =-Model!G$10 -> -30823.82 | H37: =-Model!H$10 -> -31748.535 | I37: =-Model!I$10 -> -32700.991 | J37: =-Model!J$10 -> -33682.021 | K37: =-Model!K$10 -> -34692.481 | ... M37: =-Model!M$10 -> -36805.253
A38: Incremental EBITDA | D38: =SUM(D34:D37) -> 419819.56 | E38: =SUM(E34:E37) -> 432414.14 | F38: =SUM(F34:F37) -> 445386.57 | G38: =SUM(G34:G37) -> 458748.16 | H38: =SUM(H34:H37) -> 472510.61 | I38: =SUM(I34:I37) -> 486685.93 | J38: =SUM(J34:J37) -> 501286.51 | K38: =SUM(K34:K37) -> 516325.1 | ... M38: =SUM(M34:M37) -> 547769.3
A39: Cash tax | D39: =-Inputs!$B$49*(D38-IF(D$33<=Inputs!$B$50,$C$10/Inputs!$B$50,0)) -> 0 | E39: =-Inputs!$B$49*(E38-IF(E$33<=Inputs!$B$50,$C$10/Inputs!$B$50,0)) -> 0 | F39: =-Inputs!$B$49*(F38-IF(F$33<=Inputs!$B$50,$C$10/Inputs!$B$50,0)) -> 0 | G39: =-Inputs!$B$49*(G38-IF(G$33<=Inputs!$B$50,$C$10/Inputs!$B$50,0)) -> 0 | H39: =-Inputs!$B$49*(H38-IF(H$33<=Inputs!$B$50,$C$10/Inputs!$B$50,0)) -> 0 | I39: =-Inputs!$B$49*(I38-IF(I$33<=Inputs!$B$50,$C$10/Inputs!$B$50,0)) -> 0 | J39: =-Inputs!$B$49*(J38-IF(J$33<=Inputs!$B$50,$C$10/Inputs!$B$50,0)) -> 0 | K39: =-Inputs!$B$49*(K38-IF(K$33<=Inputs!$B$50,$C$10/Inputs!$B$50,0)) -> 0 | ... M39: =-Inputs!$B$49*(M38-IF(M$33<=Inputs!$B$50,$C$10/Inputs!$B$50,0)) -> 0
A40: Conversion cost, closure and residual value | C40: =-$C$10-Inputs!$B$43/52*Model!$D$7*(Model!$D$8*(1-Inputs!$B$11)+Model!$D$9*(1-Inputs!$B$12)) -> -1308423.1 | D40: =IF(D$33=$M$33,Inputs!$B$51*$C$10,0) -> 0 | E40: =IF(E$33=$M$33,Inputs!$B$51*$C$10,0) -> 0 | F40: =IF(F$33=$M$33,Inputs!$B$51*$C$10,0) -> 0 | G40: =IF(G$33=$M$33,Inputs!$B$51*$C$10,0) -> 0 | H40: =IF(H$33=$M$33,Inputs!$B$51*$C$10,0) -> 0 | I40: =IF(I$33=$M$33,Inputs!$B$51*$C$10,0) -> 0 | J40: =IF(J$33=$M$33,Inputs!$B$51*$C$10,0) -> 0 | K40: =IF(K$33=$M$33,Inputs!$B$51*$C$10,0) -> 0 | ... M40: =IF(M$33=$M$33,Inputs!$B$51*$C$10,0) -> 0
A41: Net cash flow | C41: =C40 -> -1308423.1 | D41: =D38+D39+D40 -> 419819.56 | E41: =E38+E39+E40 -> 432414.14 | F41: =F38+F39+F40 -> 445386.57 | G41: =G38+G39+G40 -> 458748.16 | H41: =H38+H39+H40 -> 472510.61 | I41: =I38+I39+I40 -> 486685.93 | J41: =J38+J39+J40 -> 501286.51 | K41: =K38+K39+K40 -> 516325.1 | ... M41: =M38+M39+M40 -> 547769.3
A42: Cumulative cash flow | C42: =C41 -> -1308423.1 | D42: =C42+D41 -> -888603.49 | E42: =D42+E41 -> -456189.35 | F42: =E42+F41 -> -10802.784 | G42: =F42+G41 -> 447945.38 | H42: =G42+H41 -> 920455.99 | I42: =H42+I41 -> 1407141.9 | J42: =I42+J41 -> 1908428.4 | K42: =J42+K41 -> 2424753.5 | ... M42: =L42+M41 -> 3504337.7
A45: Downside case cash flows | B45: Year | C45: =Model!C$4 -> 0 | D45: =Model!D$4 -> 1 | E45: =Model!E$4 -> 2 | F45: =Model!F$4 -> 3 | G45: =Model!G$4 -> 4 | H45: =Model!H$4 -> 5 | I45: =Model!I$4 -> 6 | J45: =Model!J$4 -> 7 | ... M45: =Model!M$4 -> 10
A46: Incremental admissions revenue | D46: =Model!D$7*(1+$D$5)*((Inputs!$B$29+$D$6*(1-Inputs!$B$39))*Model!D$6)-Model!D$7*Model!D$8-Model!D$7*$D$5*$D$7*Model!D$8 -> 184905.44 | E46: =Model!E$7*(1+$D$5)*((Inputs!$B$29+$D$6*(1-Inputs!$B$39))*Model!E$6)-Model!E$7*Model!E$8-Model!E$7*$D$5*$D$7*Model!E$8 -> 190452.6 | F46: =Model!F$7*(1+$D$5)*((Inputs!$B$29+$D$6*(1-Inputs!$B$39))*Model!F$6)-Model!F$7*Model!F$8-Model!F$7*$D$5*$D$7*Model!F$8 -> 196166.18 | G46: =Model!G$7*(1+$D$5)*((Inputs!$B$29+$D$6*(1-Inputs!$B$39))*Model!G$6)-Model!G$7*Model!G$8-Model!G$7*$D$5*$D$7*Model!G$8 -> 202051.16 | H46: =Model!H$7*(1+$D$5)*((Inputs!$B$29+$D$6*(1-Inputs!$B$39))*Model!H$6)-Model!H$7*Model!H$8-Model!H$7*$D$5*$D$7*Model!H$8 -> 208112.7 | I46: =Model!I$7*(1+$D$5)*((Inputs!$B$29+$D$6*(1-Inputs!$B$39))*Model!I$6)-Model!I$7*Model!I$8-Model!I$7*$D$5*$D$7*Model!I$8 -> 214356.08 | J46: =Model!J$7*(1+$D$5)*((Inputs!$B$29+$D$6*(1-Inputs!$B$39))*Model!J$6)-Model!J$7*Model!J$8-Model!J$7*$D$5*$D$7*Model!J$8 -> 220786.76 | K46: =Model!K$7*(1+$D$5)*((Inputs!$B$29+$D$6*(1-Inputs!$B$39))*Model!K$6)-Model!K$7*Model!K$8-Model!K$7*$D$5*$D$7*Model!K$8 -> 227410.36 | ... M46: =Model!M$7*(1+$D$5)*((Inputs!$B$29+$D$6*(1-Inputs!$B$39))*Model!M$6)-Model!M$7*Model!M$8-Model!M$7*$D$5*$D$7*Model!M$8 -> 241259.65
A47: Film cost and format partner share | D47: =-Inputs!$B$11*D46-$D$8*Model!D$7*(1+$D$5)*((Inputs!$B$29+$D$6*(1-Inputs!$B$39))*Model!D$6) -> -190424.29 | E47: =-Inputs!$B$11*E46-$D$8*Model!E$7*(1+$D$5)*((Inputs!$B$29+$D$6*(1-Inputs!$B$39))*Model!E$6) -> -196137.01 | F47: =-Inputs!$B$11*F46-$D$8*Model!F$7*(1+$D$5)*((Inputs!$B$29+$D$6*(1-Inputs!$B$39))*Model!F$6) -> -202021.12 | G47: =-Inputs!$B$11*G46-$D$8*Model!G$7*(1+$D$5)*((Inputs!$B$29+$D$6*(1-Inputs!$B$39))*Model!G$6) -> -208081.76 | H47: =-Inputs!$B$11*H46-$D$8*Model!H$7*(1+$D$5)*((Inputs!$B$29+$D$6*(1-Inputs!$B$39))*Model!H$6) -> -214324.21 | I47: =-Inputs!$B$11*I46-$D$8*Model!I$7*(1+$D$5)*((Inputs!$B$29+$D$6*(1-Inputs!$B$39))*Model!I$6) -> -220753.94 | J47: =-Inputs!$B$11*J46-$D$8*Model!J$7*(1+$D$5)*((Inputs!$B$29+$D$6*(1-Inputs!$B$39))*Model!J$6) -> -227376.56 | K47: =-Inputs!$B$11*K46-$D$8*Model!K$7*(1+$D$5)*((Inputs!$B$29+$D$6*(1-Inputs!$B$39))*Model!K$6) -> -234197.85 | ... M47: =-Inputs!$B$11*M46-$D$8*Model!M$7*(1+$D$5)*((Inputs!$B$29+$D$6*(1-Inputs!$B$39))*Model!M$6) -> -248460.5
A48: Food and beverage contribution | D48: =Model!D$7*$D$5*(1-$D$7)*Model!D$9*(1-Inputs!$B$12) -> 33899.087 | E48: =Model!E$7*$D$5*(1-$D$7)*Model!E$9*(1-Inputs!$B$12) -> 34916.059 | F48: =Model!F$7*$D$5*(1-$D$7)*Model!F$9*(1-Inputs!$B$12) -> 35963.541 | G48: =Model!G$7*$D$5*(1-$D$7)*Model!G$9*(1-Inputs!$B$12) -> 37042.447 | H48: =Model!H$7*$D$5*(1-$D$7)*Model!H$9*(1-Inputs!$B$12) -> 38153.721 | I48: =Model!I$7*$D$5*(1-$D$7)*Model!I$9*(1-Inputs!$B$12) -> 39298.332 | J48: =Model!J$7*$D$5*(1-$D$7)*Model!J$9*(1-Inputs!$B$12) -> 40477.282 | K48: =Model!K$7*$D$5*(1-$D$7)*Model!K$9*(1-Inputs!$B$12) -> 41691.601 | ... M48: =Model!M$7*$D$5*(1-$D$7)*Model!M$9*(1-Inputs!$B$12) -> 44230.619
...

Sheet Sensitivity
A1: Sensitivity: NPV per converted screen
A2: Rows: attendance uplift. Columns: premium surcharge and the resulting list price in year 1 (standard price + full surcharge; the Model sheet's premium price also nets out tickets sold without the surcharge). Every other input stays at the base case.
B4: Premium surcharge | C4: =Inputs!$B$57+(0-2)*Inputs!$B$66 -> 3.5 | D4: =Inputs!$B$57+(1-2)*Inputs!$B$66 -> 4.25 | E4: =Inputs!$B$57+(2-2)*Inputs!$B$66 -> 5 | F4: =Inputs!$B$57+(3-2)*Inputs!$B$66 -> 5.75 | G4: =Inputs!$B$57+(4-2)*Inputs!$B$66 -> 6.5
B5: Premium list price | C5: =Inputs!$B$29+C4 -> 16.284802 | D5: =Inputs!$B$29+D4 -> 17.034802 | E5: =Inputs!$B$29+E4 -> 17.784802 | F5: =Inputs!$B$29+F4 -> 18.534802 | G5: =Inputs!$B$29+G4 -> 19.284802
A6: Attendance uplift | B6: =Inputs!$B$56+(0-2)*Inputs!$B$65 -> 0.5 | C6: =-Inputs!$B$61-Inputs!$B$43/52*Model!$D$7*(Model!$D$8*(1-Inputs!$B$11)+Model!$D$9*(1-Inputs!$B$12))+SUMPRODUCT(Model!$D$5:$M$5,(1-Inputs!$B$49)*(Model!$D$7:$M$7*(1+$B6)*(Model!$D$8:$M$8+C$4*(1-Inputs!$B$39)*Model!$D$6:$M$6)*(1-Inputs!$B$11-Inputs!$B$59)-Model!$D$7:$M$7*Model!$D$8:$M$8*(1+$B6*Inputs!$B$58)*(1-Inputs!$B$11)+Model!$D$7:$M$7*$B6*(1-Inputs!$B$58)*Model!$D$9:$M$9*(1-Inputs!$B$12)-Model!$D$10:$M$10)+Inputs!$B$49*Inputs!$B$61/Inputs!$B$50*(Model!$D$4:$M$4<=Inputs!$B$50))+Inputs!$B$51*Inputs!$B$61*Model!$M$5 -> -1038250.2 | D6: =-Inputs!$B$61-Inputs!$B$43/52*Model!$D$7*(Model!$D$8*(1-Inputs!$B$11)+Model!$D$9*(1-Inputs!$B$12))+SUMPRODUCT(Model!$D$5:$M$5,(1-Inputs!$B$49)*(Model!$D$7:$M$7*(1+$B6)*(Model!$D$8:$M$8+D$4*(1-Inputs!$B$39)*Model!$D$6:$M$6)*(1-Inputs!$B$11-Inputs!$B$59)-Model!$D$7:$M$7*Model!$D$8:$M$8*(1+$B6*Inputs!$B$58)*(1-Inputs!$B$11)+Model!$D$7:$M$7*$B6*(1-Inputs!$B$58)*Model!$D$9:$M$9*(1-Inputs!$B$12)-Model!$D$10:$M$10)+Inputs!$B$49*Inputs!$B$61/Inputs!$B$50*(Model!$D$4:$M$4<=Inputs!$B$50))+Inputs!$B$51*Inputs!$B$61*Model!$M$5 -> -966145.05 | E6: =-Inputs!$B$61-Inputs!$B$43/52*Model!$D$7*(Model!$D$8*(1-Inputs!$B$11)+Model!$D$9*(1-Inputs!$B$12))+SUMPRODUCT(Model!$D$5:$M$5,(1-Inputs!$B$49)*(Model!$D$7:$M$7*(1+$B6)*(Model!$D$8:$M$8+E$4*(1-Inputs!$B$39)*Model!$D$6:$M$6)*(1-Inputs!$B$11-Inputs!$B$59)-Model!$D$7:$M$7*Model!$D$8:$M$8*(1+$B6*Inputs!$B$58)*(1-Inputs!$B$11)+Model!$D$7:$M$7*$B6*(1-Inputs!$B$58)*Model!$D$9:$M$9*(1-Inputs!$B$12)-Model!$D$10:$M$10)+Inputs!$B$49*Inputs!$B$61/Inputs!$B$50*(Model!$D$4:$M$4<=Inputs!$B$50))+Inputs!$B$51*Inputs!$B$61*Model!$M$5 -> -894039.94 | F6: =-Inputs!$B$61-Inputs!$B$43/52*Model!$D$7*(Model!$D$8*(1-Inputs!$B$11)+Model!$D$9*(1-Inputs!$B$12))+SUMPRODUCT(Model!$D$5:$M$5,(1-Inputs!$B$49)*(Model!$D$7:$M$7*(1+$B6)*(Model!$D$8:$M$8+F$4*(1-Inputs!$B$39)*Model!$D$6:$M$6)*(1-Inputs!$B$11-Inputs!$B$59)-Model!$D$7:$M$7*Model!$D$8:$M$8*(1+$B6*Inputs!$B$58)*(1-Inputs!$B$11)+Model!$D$7:$M$7*$B6*(1-Inputs!$B$58)*Model!$D$9:$M$9*(1-Inputs!$B$12)-Model!$D$10:$M$10)+Inputs!$B$49*Inputs!$B$61/Inputs!$B$50*(Model!$D$4:$M$4<=Inputs!$B$50))+Inputs!$B$51*Inputs!$B$61*Model!$M$5 -> -821934.82 | G6: =-Inputs!$B$61-Inputs!$B$43/52*Model!$D$7*(Model!$D$8*(1-Inputs!$B$11)+Model!$D$9*(1-Inputs!$B$12))+SUMPRODUCT(Model!$D$5:$M$5,(1-Inputs!$B$49)*(Model!$D$7:$M$7*(1+$B6)*(Model!$D$8:$M$8+G$4*(1-Inputs!$B$39)*Model!$D$6:$M$6)*(1-Inputs!$B$11-Inputs!$B$59)-Model!$D$7:$M$7*Model!$D$8:$M$8*(1+$B6*Inputs!$B$58)*(1-Inputs!$B$11)+Model!$D$7:$M$7*$B6*(1-Inputs!$B$58)*Model!$D$9:$M$9*(1-Inputs!$B$12)-Model!$D$10:$M$10)+Inputs!$B$49*Inputs!$B$61/Inputs!$B$50*(Model!$D$4:$M$4<=Inputs!$B$50))+Inputs!$B$51*Inputs!$B$61*Model!$M$5 -> -749829.71
B7: =Inputs!$B$56+(1-2)*Inputs!$B$65 -> 0.75 | C7: =-Inputs!$B$61-Inputs!$B$43/52*Model!$D$7*(Model!$D$8*(1-Inputs!$B$11)+Model!$D$9*(1-Inputs!$B$12))+SUMPRODUCT(Model!$D$5:$M$5,(1-Inputs!$B$49)*(Model!$D$7:$M$7*(1+$B7)*(Model!$D$8:$M$8+C$4*(1-Inputs!$B$39)*Model!$D$6:$M$6)*(1-Inputs!$B$11-Inputs!$B$59)-Model!$D$7:$M$7*Model!$D$8:$M$8*(1+$B7*Inputs!$B$58)*(1-Inputs!$B$11)+Model!$D$7:$M$7*$B7*(1-Inputs!$B$58)*Model!$D$9:$M$9*(1-Inputs!$B$12)-Model!$D$10:$M$10)+Inputs!$B$49*Inputs!$B$61/Inputs!$B$50*(Model!$D$4:$M$4<=Inputs!$B$50))+Inputs!$B$51*Inputs!$B$61*Model!$M$5 -> -722217.52 | D7: =-Inputs!$B$61-Inputs!$B$43/52*Model!$D$7*(Model!$D$8*(1-Inputs!$B$11)+Model!$D$9*(1-Inputs!$B$12))+SUMPRODUCT(Model!$D$5:$M$5,(1-Inputs!$B$49)*(Model!$D$7:$M$7*(1+$B7)*(Model!$D$8:$M$8+D$4*(1-Inputs!$B$39)*Model!$D$6:$M$6)*(1-Inputs!$B$11-Inputs!$B$59)-Model!$D$7:$M$7*Model!$D$8:$M$8*(1+$B7*Inputs!$B$58)*(1-Inputs!$B$11)+Model!$D$7:$M$7*$B7*(1-Inputs!$B$58)*Model!$D$9:$M$9*(1-Inputs!$B$12)-Model!$D$10:$M$10)+Inputs!$B$49*Inputs!$B$61/Inputs!$B$50*(Model!$D$4:$M$4<=Inputs!$B$50))+Inputs!$B$51*Inputs!$B$61*Model!$M$5 -> -638094.88 | E7: =-Inputs!$B$61-Inputs!$B$43/52*Model!$D$7*(Model!$D$8*(1-Inputs!$B$11)+Model!$D$9*(1-Inputs!$B$12))+SUMPRODUCT(Model!$D$5:$M$5,(1-Inputs!$B$49)*(Model!$D$7:$M$7*(1+$B7)*(Model!$D$8:$M$8+E$4*(1-Inputs!$B$39)*Model!$D$6:$M$6)*(1-Inputs!$B$11-Inputs!$B$59)-Model!$D$7:$M$7*Model!$D$8:$M$8*(1+$B7*Inputs!$B$58)*(1-Inputs!$B$11)+Model!$D$7:$M$7*$B7*(1-Inputs!$B$58)*Model!$D$9:$M$9*(1-Inputs!$B$12)-Model!$D$10:$M$10)+Inputs!$B$49*Inputs!$B$61/Inputs!$B$50*(Model!$D$4:$M$4<=Inputs!$B$50))+Inputs!$B$51*Inputs!$B$61*Model!$M$5 -> -553972.25 | F7: =-Inputs!$B$61-Inputs!$B$43/52*Model!$D$7*(Model!$D$8*(1-Inputs!$B$11)+Model!$D$9*(1-Inputs!$B$12))+SUMPRODUCT(Model!$D$5:$M$5,(1-Inputs!$B$49)*(Model!$D$7:$M$7*(1+$B7)*(Model!$D$8:$M$8+F$4*(1-Inputs!$B$39)*Model!$D$6:$M$6)*(1-Inputs!$B$11-Inputs!$B$59)-Model!$D$7:$M$7*Model!$D$8:$M$8*(1+$B7*Inputs!$B$58)*(1-Inputs!$B$11)+Model!$D$7:$M$7*$B7*(1-Inputs!$B$58)*Model!$D$9:$M$9*(1-Inputs!$B$12)-Model!$D$10:$M$10)+Inputs!$B$49*Inputs!$B$61/Inputs!$B$50*(Model!$D$4:$M$4<=Inputs!$B$50))+Inputs!$B$51*Inputs!$B$61*Model!$M$5 -> -469849.61 | G7: =-Inputs!$B$61-Inputs!$B$43/52*Model!$D$7*(Model!$D$8*(1-Inputs!$B$11)+Model!$D$9*(1-Inputs!$B$12))+SUMPRODUCT(Model!$D$5:$M$5,(1-Inputs!$B$49)*(Model!$D$7:$M$7*(1+$B7)*(Model!$D$8:$M$8+G$4*(1-Inputs!$B$39)*Model!$D$6:$M$6)*(1-Inputs!$B$11-Inputs!$B$59)-Model!$D$7:$M$7*Model!$D$8:$M$8*(1+$B7*Inputs!$B$58)*(1-Inputs!$B$11)+Model!$D$7:$M$7*$B7*(1-Inputs!$B$58)*Model!$D$9:$M$9*(1-Inputs!$B$12)-Model!$D$10:$M$10)+Inputs!$B$49*Inputs!$B$61/Inputs!$B$50*(Model!$D$4:$M$4<=Inputs!$B$50))+Inputs!$B$51*Inputs!$B$61*Model!$M$5 -> -385726.97
B8: =Inputs!$B$56+(2-2)*Inputs!$B$65 -> 1 | C8: =-Inputs!$B$61-Inputs!$B$43/52*Model!$D$7*(Model!$D$8*(1-Inputs!$B$11)+Model!$D$9*(1-Inputs!$B$12))+SUMPRODUCT(Model!$D$5:$M$5,(1-Inputs!$B$49)*(Model!$D$7:$M$7*(1+$B8)*(Model!$D$8:$M$8+C$4*(1-Inputs!$B$39)*Model!$D$6:$M$6)*(1-Inputs!$B$11-Inputs!$B$59)-Model!$D$7:$M$7*Model!$D$8:$M$8*(1+$B8*Inputs!$B$58)*(1-Inputs!$B$11)+Model!$D$7:$M$7*$B8*(1-Inputs!$B$58)*Model!$D$9:$M$9*(1-Inputs!$B$12)-Model!$D$10:$M$10)+Inputs!$B$49*Inputs!$B$61/Inputs!$B$50*(Model!$D$4:$M$4<=Inputs!$B$50))+Inputs!$B$51*Inputs!$B$61*Model!$M$5 -> -406184.86 | D8: =-Inputs!$B$61-Inputs!$B$43/52*Model!$D$7*(Model!$D$8*(1-Inputs!$B$11)+Model!$D$9*(1-Inputs!$B$12))+SUMPRODUCT(Model!$D$5:$M$5,(1-Inputs!$B$49)*(Model!$D$7:$M$7*(1+$B8)*(Model!$D$8:$M$8+D$4*(1-Inputs!$B$39)*Model!$D$6:$M$6)*(1-Inputs!$B$11-Inputs!$B$59)-Model!$D$7:$M$7*Model!$D$8:$M$8*(1+$B8*Inputs!$B$58)*(1-Inputs!$B$11)+Model!$D$7:$M$7*$B8*(1-Inputs!$B$58)*Model!$D$9:$M$9*(1-Inputs!$B$12)-Model!$D$10:$M$10)+Inputs!$B$49*Inputs!$B$61/Inputs!$B$50*(Model!$D$4:$M$4<=Inputs!$B$50))+Inputs!$B$51*Inputs!$B$61*Model!$M$5 -> -310044.71 | E8: =-Inputs!$B$61-Inputs!$B$43/52*Model!$D$7*(Model!$D$8*(1-Inputs!$B$11)+Model!$D$9*(1-Inputs!$B$12))+SUMPRODUCT(Model!$D$5:$M$5,(1-Inputs!$B$49)*(Model!$D$7:$M$7*(1+$B8)*(Model!$D$8:$M$8+E$4*(1-Inputs!$B$39)*Model!$D$6:$M$6)*(1-Inputs!$B$11-Inputs!$B$59)-Model!$D$7:$M$7*Model!$D$8:$M$8*(1+$B8*Inputs!$B$58)*(1-Inputs!$B$11)+Model!$D$7:$M$7*$B8*(1-Inputs!$B$58)*Model!$D$9:$M$9*(1-Inputs!$B$12)-Model!$D$10:$M$10)+Inputs!$B$49*Inputs!$B$61/Inputs!$B$50*(Model!$D$4:$M$4<=Inputs!$B$50))+Inputs!$B$51*Inputs!$B$61*Model!$M$5 -> -213904.55 | F8: =-Inputs!$B$61-Inputs!$B$43/52*Model!$D$7*(Model!$D$8*(1-Inputs!$B$11)+Model!$D$9*(1-Inputs!$B$12))+SUMPRODUCT(Model!$D$5:$M$5,(1-Inputs!$B$49)*(Model!$D$7:$M$7*(1+$B8)*(Model!$D$8:$M$8+F$4*(1-Inputs!$B$39)*Model!$D$6:$M$6)*(1-Inputs!$B$11-Inputs!$B$59)-Model!$D$7:$M$7*Model!$D$8:$M$8*(1+$B8*Inputs!$B$58)*(1-Inputs!$B$11)+Model!$D$7:$M$7*$B8*(1-Inputs!$B$58)*Model!$D$9:$M$9*(1-Inputs!$B$12)-Model!$D$10:$M$10)+Inputs!$B$49*Inputs!$B$61/Inputs!$B$50*(Model!$D$4:$M$4<=Inputs!$B$50))+Inputs!$B$51*Inputs!$B$61*Model!$M$5 -> -117764.4 | G8: =-Inputs!$B$61-Inputs!$B$43/52*Model!$D$7*(Model!$D$8*(1-Inputs!$B$11)+Model!$D$9*(1-Inputs!$B$12))+SUMPRODUCT(Model!$D$5:$M$5,(1-Inputs!$B$49)*(Model!$D$7:$M$7*(1+$B8)*(Model!$D$8:$M$8+G$4*(1-Inputs!$B$39)*Model!$D$6:$M$6)*(1-Inputs!$B$11-Inputs!$B$59)-Model!$D$7:$M$7*Model!$D$8:$M$8*(1+$B8*Inputs!$B$58)*(1-Inputs!$B$11)+Model!$D$7:$M$7*$B8*(1-Inputs!$B$58)*Model!$D$9:$M$9*(1-Inputs!$B$12)-Model!$D$10:$M$10)+Inputs!$B$49*Inputs!$B$61/Inputs!$B$50*(Model!$D$4:$M$4<=Inputs!$B$50))+Inputs!$B$51*Inputs!$B$61*Model!$M$5 -> -21624.244
B9: =Inputs!$B$56+(3-2)*Inputs!$B$65 -> 1.25 | C9: =-Inputs!$B$61-Inputs!$B$43/52*Model!$D$7*(Model!$D$8*(1-Inputs!$B$11)+Model!$D$9*(1-Inputs!$B$12))+SUMPRODUCT(Model!$D$5:$M$5,(1-Inputs!$B$49)*(Model!$D$7:$M$7*(1+$B9)*(Model!$D$8:$M$8+C$4*(1-Inputs!$B$39)*Model!$D$6:$M$6)*(1-Inputs!$B$11-Inputs!$B$59)-Model!$D$7:$M$7*Model!$D$8:$M$8*(1+$B9*Inputs!$B$58)*(1-Inputs!$B$11)+Model!$D$7:$M$7*$B9*(1-Inputs!$B$58)*Model!$D$9:$M$9*(1-Inputs!$B$12)-Model!$D$10:$M$10)+Inputs!$B$49*Inputs!$B$61/Inputs!$B$50*(Model!$D$4:$M$4<=Inputs!$B$50))+Inputs!$B$51*Inputs!$B$61*Model!$M$5 -> -90152.212 | D9: =-Inputs!$B$61-Inputs!$B$43/52*Model!$D$7*(Model!$D$8*(1-Inputs!$B$11)+Model!$D$9*(1-Inputs!$B$12))+SUMPRODUCT(Model!$D$5:$M$5,(1-Inputs!$B$49)*(Model!$D$7:$M$7*(1+$B9)*(Model!$D$8:$M$8+D$4*(1-Inputs!$B$39)*Model!$D$6:$M$6)*(1-Inputs!$B$11-Inputs!$B$59)-Model!$D$7:$M$7*Model!$D$8:$M$8*(1+$B9*Inputs!$B$58)*(1-Inputs!$B$11)+Model!$D$7:$M$7*$B9*(1-Inputs!$B$58)*Model!$D$9:$M$9*(1-Inputs!$B$12)-Model!$D$10:$M$10)+Inputs!$B$49*Inputs!$B$61/Inputs!$B$50*(Model!$D$4:$M$4<=Inputs!$B$50))+Inputs!$B$51*Inputs!$B$61*Model!$M$5 -> 18005.463 | E9: =-Inputs!$B$61-Inputs!$B$43/52*Model!$D$7*(Model!$D$8*(1-Inputs!$B$11)+Model!$D$9*(1-Inputs!$B$12))+SUMPRODUCT(Model!$D$5:$M$5,(1-Inputs!$B$49)*(Model!$D$7:$M$7*(1+$B9)*(Model!$D$8:$M$8+E$4*(1-Inputs!$B$39)*Model!$D$6:$M$6)*(1-Inputs!$B$11-Inputs!$B$59)-Model!$D$7:$M$7*Model!$D$8:$M$8*(1+$B9*Inputs!$B$58)*(1-Inputs!$B$11)+Model!$D$7:$M$7*$B9*(1-Inputs!$B$58)*Model!$D$9:$M$9*(1-Inputs!$B$12)-Model!$D$10:$M$10)+Inputs!$B$49*Inputs!$B$61/Inputs!$B$50*(Model!$D$4:$M$4<=Inputs!$B$50))+Inputs!$B$51*Inputs!$B$61*Model!$M$5 -> 126163.14 | F9: =-Inputs!$B$61-Inputs!$B$43/52*Model!$D$7*(Model!$D$8*(1-Inputs!$B$11)+Model!$D$9*(1-Inputs!$B$12))+SUMPRODUCT(Model!$D$5:$M$5,(1-Inputs!$B$49)*(Model!$D$7:$M$7*(1+$B9)*(Model!$D$8:$M$8+F$4*(1-Inputs!$B$39)*Model!$D$6:$M$6)*(1-Inputs!$B$11-Inputs!$B$59)-Model!$D$7:$M$7*Model!$D$8:$M$8*(1+$B9*Inputs!$B$58)*(1-Inputs!$B$11)+Model!$D$7:$M$7*$B9*(1-Inputs!$B$58)*Model!$D$9:$M$9*(1-Inputs!$B$12)-Model!$D$10:$M$10)+Inputs!$B$49*Inputs!$B$61/Inputs!$B$50*(Model!$D$4:$M$4<=Inputs!$B$50))+Inputs!$B$51*Inputs!$B$61*Model!$M$5 -> 234320.81 | G9: =-Inputs!$B$61-Inputs!$B$43/52*Model!$D$7*(Model!$D$8*(1-Inputs!$B$11)+Model!$D$9*(1-Inputs!$B$12))+SUMPRODUCT(Model!$D$5:$M$5,(1-Inputs!$B$49)*(Model!$D$7:$M$7*(1+$B9)*(Model!$D$8:$M$8+G$4*(1-Inputs!$B$39)*Model!$D$6:$M$6)*(1-Inputs!$B$11-Inputs!$B$59)-Model!$D$7:$M$7*Model!$D$8:$M$8*(1+$B9*Inputs!$B$58)*(1-Inputs!$B$11)+Model!$D$7:$M$7*$B9*(1-Inputs!$B$58)*Model!$D$9:$M$9*(1-Inputs!$B$12)-Model!$D$10:$M$10)+Inputs!$B$49*Inputs!$B$61/Inputs!$B$50*(Model!$D$4:$M$4<=Inputs!$B$50))+Inputs!$B$51*Inputs!$B$61*Model!$M$5 -> 342478.49
B10: =Inputs!$B$56+(4-2)*Inputs!$B$65 -> 1.5 | C10: =-Inputs!$B$61-Inputs!$B$43/52*Model!$D$7*(Model!$D$8*(1-Inputs!$B$11)+Model!$D$9*(1-Inputs!$B$12))+SUMPRODUCT(Model!$D$5:$M$5,(1-Inputs!$B$49)*(Model!$D$7:$M$7*(1+$B10)*(Model!$D$8:$M$8+C$4*(1-Inputs!$B$39)*Model!$D$6:$M$6)*(1-Inputs!$B$11-Inputs!$B$59)-Model!$D$7:$M$7*Model!$D$8:$M$8*(1+$B10*Inputs!$B$58)*(1-Inputs!$B$11)+Model!$D$7:$M$7*$B10*(1-Inputs!$B$58)*Model!$D$9:$M$9*(1-Inputs!$B$12)-Model!$D$10:$M$10)+Inputs!$B$49*Inputs!$B$61/Inputs!$B$50*(Model!$D$4:$M$4<=Inputs!$B$50))+Inputs!$B$51*Inputs!$B$61*Model!$M$5 -> 225880.44 | D10: =-Inputs!$B$61-Inputs!$B$43/52*Model!$D$7*(Model!$D$8*(1-Inputs!$B$11)+Model!$D$9*(1-Inputs!$B$12))+SUMPRODUCT(Model!$D$5:$M$5,(1-Inputs!$B$49)*(Model!$D$7:$M$7*(1+$B10)*(Model!$D$8:$M$8+D$4*(1-Inputs!$B$39)*Model!$D$6:$M$6)*(1-Inputs!$B$11-Inputs!$B$59)-Model!$D$7:$M$7*Model!$D$8:$M$8*(1+$B10*Inputs!$B$58)*(1-Inputs!$B$11)+Model!$D$7:$M$7*$B10*(1-Inputs!$B$58)*Model!$D$9:$M$9*(1-Inputs!$B$12)-Model!$D$10:$M$10)+Inputs!$B$49*Inputs!$B$61/Inputs!$B$50*(Model!$D$4:$M$4<=Inputs!$B$50))+Inputs!$B$51*Inputs!$B$61*Model!$M$5 -> 346055.63 | E10: =-Inputs!$B$61-Inputs!$B$43/52*Model!$D$7*(Model!$D$8*(1-Inputs!$B$11)+Model!$D$9*(1-Inputs!$B$12))+SUMPRODUCT(Model!$D$5:$M$5,(1-Inputs!$B$49)*(Model!$D$7:$M$7*(1+$B10)*(Model!$D$8:$M$8+E$4*(1-Inputs!$B$39)*Model!$D$6:$M$6)*(1-Inputs!$B$11-Inputs!$B$59)-Model!$D$7:$M$7*Model!$D$8:$M$8*(1+$B10*Inputs!$B$58)*(1-Inputs!$B$11)+Model!$D$7:$M$7*$B10*(1-Inputs!$B$58)*Model!$D$9:$M$9*(1-Inputs!$B$12)-Model!$D$10:$M$10)+Inputs!$B$49*Inputs!$B$61/Inputs!$B$50*(Model!$D$4:$M$4<=Inputs!$B$50))+Inputs!$B$51*Inputs!$B$61*Model!$M$5 -> 466230.83 | F10: =-Inputs!$B$61-Inputs!$B$43/52*Model!$D$7*(Model!$D$8*(1-Inputs!$B$11)+Model!$D$9*(1-Inputs!$B$12))+SUMPRODUCT(Model!$D$5:$M$5,(1-Inputs!$B$49)*(Model!$D$7:$M$7*(1+$B10)*(Model!$D$8:$M$8+F$4*(1-Inputs!$B$39)*Model!$D$6:$M$6)*(1-Inputs!$B$11-Inputs!$B$59)-Model!$D$7:$M$7*Model!$D$8:$M$8*(1+$B10*Inputs!$B$58)*(1-Inputs!$B$11)+Model!$D$7:$M$7*$B10*(1-Inputs!$B$58)*Model!$D$9:$M$9*(1-Inputs!$B$12)-Model!$D$10:$M$10)+Inputs!$B$49*Inputs!$B$61/Inputs!$B$50*(Model!$D$4:$M$4<=Inputs!$B$50))+Inputs!$B$51*Inputs!$B$61*Model!$M$5 -> 586406.02 | G10: =-Inputs!$B$61-Inputs!$B$43/52*Model!$D$7*(Model!$D$8*(1-Inputs!$B$11)+Model!$D$9*(1-Inputs!$B$12))+SUMPRODUCT(Model!$D$5:$M$5,(1-Inputs!$B$49)*(Model!$D$7:$M$7*(1+$B10)*(Model!$D$8:$M$8+G$4*(1-Inputs!$B$39)*Model!$D$6:$M$6)*(1-Inputs!$B$11-Inputs!$B$59)-Model!$D$7:$M$7*Model!$D$8:$M$8*(1+$B10*Inputs!$B$58)*(1-Inputs!$B$11)+Model!$D$7:$M$7*$B10*(1-Inputs!$B$58)*Model!$D$9:$M$9*(1-Inputs!$B$12)-Model!$D$10:$M$10)+Inputs!$B$49*Inputs!$B$61/Inputs!$B$50*(Model!$D$4:$M$4<=Inputs!$B$50))+Inputs!$B$51*Inputs!$B$61*Model!$M$5 -> 706581.22
A12: Check: centre cell = Scenarios base NPV | B12: =IF(ABS(E8-Scenarios!B13)<0.5,"OK","CHECK") -> OK
A14: Break-even points (base case, one input moved at a time)
A15: NPV with no attendance uplift | B15: =-Inputs!$B$61-Inputs!$B$43/52*Model!$D$7*(Model!$D$8*(1-Inputs!$B$11)+Model!$D$9*(1-Inputs!$B$12))+SUMPRODUCT(Model!$D$5:$M$5,(1-Inputs!$B$49)*(Model!$D$7:$M$7*(1+0)*(Model!$D$8:$M$8+Inputs!$B$57*(1-Inputs!$B$39)*Model!$D$6:$M$6)*(1-Inputs!$B$11-Inputs!$B$59)-Model!$D$7:$M$7*Model!$D$8:$M$8*(1+0*Inputs!$B$58)*(1-Inputs!$B$11)+Model!$D$7:$M$7*0*(1-Inputs!$B$58)*Model!$D$9:$M$9*(1-Inputs!$B$12)-Model!$D$10:$M$10)+Inputs!$B$49*Inputs!$B$61/Inputs!$B$50*(Model!$D$4:$M$4<=Inputs!$B$50))+Inputs!$B$51*Inputs!$B$61*Model!$M$5 -> -1574175.3
A16: NPV with 100% attendance uplift | B16: =-Inputs!$B$61-Inputs!$B$43/52*Model!$D$7*(Model!$D$8*(1-Inputs!$B$11)+Model!$D$9*(1-Inputs!$B$12))+SUMPRODUCT(Model!$D$5:$M$5,(1-Inputs!$B$49)*(Model!$D$7:$M$7*(1+1)*(Model!$D$8:$M$8+Inputs!$B$57*(1-Inputs!$B$39)*Model!$D$6:$M$6)*(1-Inputs!$B$11-Inputs!$B$59)-Model!$D$7:$M$7*Model!$D$8:$M$8*(1+1*Inputs!$B$58)*(1-Inputs!$B$11)+Model!$D$7:$M$7*1*(1-Inputs!$B$58)*Model!$D$9:$M$9*(1-Inputs!$B$12)-Model!$D$10:$M$10)+Inputs!$B$49*Inputs!$B$61/Inputs!$B$50*(Model!$D$4:$M$4<=Inputs!$B$50))+Inputs!$B$51*Inputs!$B$61*Model!$M$5 -> -213904.55
A17: Break-even attendance uplift | B17: =-B15/(B16-B15) -> 1.1572515
A18: NPV with no premium surcharge | B18: =-Inputs!$B$61-Inputs!$B$43/52*Model!$D$7*(Model!$D$8*(1-Inputs!$B$11)+Model!$D$9*(1-Inputs!$B$12))+SUMPRODUCT(Model!$D$5:$M$5,(1-Inputs!$B$49)*(Model!$D$7:$M$7*(1+Inputs!$B$56)*(Model!$D$8:$M$8+0*(1-Inputs!$B$39)*Model!$D$6:$M$6)*(1-Inputs!$B$11-Inputs!$B$59)-Model!$D$7:$M$7*Model!$D$8:$M$8*(1+Inputs!$B$56*Inputs!$B$58)*(1-Inputs!$B$11)+Model!$D$7:$M$7*Inputs!$B$56*(1-Inputs!$B$58)*Model!$D$9:$M$9*(1-Inputs!$B$12)-Model!$D$10:$M$10)+Inputs!$B$49*Inputs!$B$61/Inputs!$B$50*(Model!$D$4:$M$4<=Inputs!$B$50))+Inputs!$B$51*Inputs!$B$61*Model!$M$5 -> -854838.92
A19: NPV with a $1.00 premium surcharge | B19: =-Inputs!$B$61-Inputs!$B$43/52*Model!$D$7*(Model!$D$8*(1-Inputs!$B$11)+Model!$D$9*(1-Inputs!$B$12))+SUMPRODUCT(Model!$D$5:$M$5,(1-Inputs!$B$49)*(Model!$D$7:$M$7*(1+Inputs!$B$56)*(Model!$D$8:$M$8+1*(1-Inputs!$B$39)*Model!$D$6:$M$6)*(1-Inputs!$B$11-Inputs!$B$59)-Model!$D$7:$M$7*Model!$D$8:$M$8*(1+Inputs!$B$56*Inputs!$B$58)*(1-Inputs!$B$11)+Model!$D$7:$M$7*Inputs!$B$56*(1-Inputs!$B$58)*Model!$D$9:$M$9*(1-Inputs!$B$12)-Model!$D$10:$M$10)+Inputs!$B$49*Inputs!$B$61/Inputs!$B$50*(Model!$D$4:$M$4<=Inputs!$B$50))+Inputs!$B$51*Inputs!$B$61*Model!$M$5 -> -726652.05
A20: Break-even premium surcharge | B20: =-B18/(B19-B18) -> 6.6686931
A21: NPV is a straight line in each of these inputs, so two points give the break-even exactly.

Sheet Summary
A1: Summary: should the chain convert standard screens to premium large format?
A3: Recommendation | B3: =IF(AND(Scenarios!B13>0,Scenarios!C13>0,Scenarios!D13>0),"Convert: all three scenarios clear the discount rate.",IF(Scenarios!B13>0,"Convert, with care: the base case clears the discount rate but the downside does not.",IF(Scenarios!C13>0,"Convert selectively: only screens expected to beat the break-even attendance uplift below.","Do not convert: no scenario clears the discount rate."))) -> Convert selectively: only screens expected to beat the break-even attendance uplift below.
A5: Per converted screen | B5: Base | C5: Upside | D5: Downside
A6: Net present value (NPV) | B6: =Scenarios!B13 -> -213904.55 | C6: =Scenarios!C13 -> 1647821.5 | D6: =Scenarios!D13 -> -1794151.4
A7: Internal rate of return (IRR) | B7: =Scenarios!B14 -> 0.061365528 | C7: =Scenarios!C14 -> 0.32500643 | D7: =Scenarios!D14 -> Not meaningful
A8: Payback period | B8: =Scenarios!B15 -> 7.4880325 | C8: =Scenarios!C15 -> 3.0235484 | D8: =Scenarios!D15 -> Not within 10 years
A9: 10-year cumulative cash flow | B9: =Scenarios!B16 -> 560821.79 | C9: =Scenarios!C16 -> 3504337.7 | D9: =Scenarios!D16 -> -1793390.4
A10: Incremental EBITDA, year 1 | B10: =Scenarios!B17 -> 175191.18 | C10: =Scenarios!C17 -> 419819.56 | D10: =Scenarios!D17 -> 172.07374
A11: Conversion cost | B11: =Scenarios!B10 -> 1391257.1 | C11: =Scenarios!C10 -> 1252131.4 | D11: =Scenarios!D10 -> 1739071.4
A13: Break-even attendance uplift (base case) | B13: =Sensitivity!B17 -> 1.1572515
A14: Break-even premium surcharge (base case) | B14: =Sensitivity!B20 -> 6.6686931
A15: Discount rate | B15: =Inputs!$B$52 -> 0.095
A16: Model checks | B16: =IF(AND(Scenarios!B19="OK",Sensitivity!B12="OK"),"OK","CHECK") -> OK
A18: What drives the answer
A19: 1. Attendance uplift and cannibalization decide the result. Only net new patrons add food and beverage profit, and every extra ticket on the converted screen pays film rent and the partner's share.
A20: 2. The partner's share applies to the whole screen's box office, including tickets the screen sold before conversion, so better deal terms raise NPV directly.
A21: 3. A-List subscribers book premium formats at no extra cost, so a higher subscriber mix erodes the surcharge.
A22: 4. Results depend on a slate of films made for premium formats. A weak year cuts both uplift and surcharge.
A23: 5. Construction overruns and weeks closed hit the investment up front, before any uplift arrives.

Sheet Checks
A1: Checks: recompute the results a second way with Excel's own functions
A2: The Scenarios sheet discounts each year with the factors on the Model sheet. Here Excel's NPV function discounts the same cash flows at the Inputs discount rate, and IRR is tested by discounting at the IRR, which should give zero.
A4: Check | B4: Base | C4: Upside | D4: Downside
A5: NPV on the Scenarios sheet | B5: =Scenarios!B13 -> -213904.55 | C5: =Scenarios!C13 -> 1647821.5 | D5: =Scenarios!D13 -> -1794151.4
A6: NPV with Excel's NPV function | B6: =Scenarios!C29+NPV(Inputs!$B$52,Scenarios!D29:M29) -> -213904.55 | C6: =Scenarios!C41+NPV(Inputs!$B$52,Scenarios!D41:M41) -> 1647821.5 | D6: =Scenarios!C53+NPV(Inputs!$B$52,Scenarios!D53:M53) -> -1794151.4
A7: Difference | B7: =B6-B5 -> 0 | C7: =C6-C5 -> 0 | D7: =D6-D5 -> 0
A8: NPV at the IRR (should be about zero) | B8: =IF(ISNUMBER(Scenarios!B14),Scenarios!C29+NPV(Scenarios!B14,Scenarios!D29:M29),"No IRR") -> -4.6566129e-10 | C8: =IF(ISNUMBER(Scenarios!C14),Scenarios!C41+NPV(Scenarios!C14,Scenarios!D41:M41),"No IRR") -> 4.6566129e-10 | D8: =IF(ISNUMBER(Scenarios!D14),Scenarios!C53+NPV(Scenarios!D14,Scenarios!D53:M53),"No IRR") -> No IRR
A9: Check | B9: =IF(AND(ABS(B7)<0.5,OR(NOT(ISNUMBER(B8)),ABS(IF(ISNUMBER(B8),B8,0))<0.5)),"OK","CHECK") -> OK | C9: =IF(AND(ABS(C7)<0.5,OR(NOT(ISNUMBER(C8)),ABS(IF(ISNUMBER(C8),C8,0))<0.5)),"OK","CHECK") -> OK | D9: =IF(AND(ABS(D7)<0.5,OR(NOT(ISNUMBER(D8)),ABS(IF(ISNUMBER(D8),D8,0))<0.5)),"OK","CHECK") -> OK
A11: All checks (this sheet, Scenarios!B19 and Sensitivity!B12) | B11: =IF(AND(B9="OK",C9="OK",D9="OK",Scenarios!B19="OK",Sensitivity!B12="OK"),"OK","CHECK") -> OK

Sheet scenario_results
A1: scenario | B1: attendance_uplift | C1: premium_surcharge | D1: cannibalization_share | E1: partner_share | F1: conversion_cost | G1: npv | H1: irr | I1: payback_years | J1: cumulative_cash_flow_10yr | K1: ebitda_year1
A2: Base | B2: =ROUND(Scenarios!B5,4) -> 1 | C2: =ROUND(Scenarios!B6,2) -> 5 | D2: =ROUND(Scenarios!B7,4) -> 0.5 | E2: =ROUND(Scenarios!B8,4) -> 0.1 | F2: =ROUND(Scenarios!B10,0) -> 1391257 | G2: =ROUND(Scenarios!B13,0) -> -213905 | H2: =IF(ISNUMBER(Scenarios!B14),ROUND(Scenarios!B14,4),"") -> 0.0614 | I2: =IF(ISNUMBER(Scenarios!B15),ROUND(Scenarios!B15,1),"") -> 7.5 | J2: =ROUND(Scenarios!B16,0) -> 560822 | K2: =ROUND(Scenarios!B17,0) -> 175191
A3: Upside | B3: =ROUND(Scenarios!C5,4) -> 1.5 | C3: =ROUND(Scenarios!C6,2) -> 6.5 | D3: =ROUND(Scenarios!C7,4) -> 0.35 | E3: =ROUND(Scenarios!C8,4) -> 0.075 | F3: =ROUND(Scenarios!C10,0) -> 1252131 | G3: =ROUND(Scenarios!C13,0) -> 1647821 | H3: =IF(ISNUMBER(Scenarios!C14),ROUND(Scenarios!C14,4),"") -> 0.325 | I3: =IF(ISNUMBER(Scenarios!C15),ROUND(Scenarios!C15,1),"") -> 3 | J3: =ROUND(Scenarios!C16,0) -> 3504338 | K3: =ROUND(Scenarios!C17,0) -> 419820
A4: Downside | B4: =ROUND(Scenarios!D5,4) -> 0.5 | C4: =ROUND(Scenarios!D6,2) -> 3.5 | D4: =ROUND(Scenarios!D7,4) -> 0.65 | E4: =ROUND(Scenarios!D8,4) -> 0.1468 | F4: =ROUND(Scenarios!D10,0) -> 1739071 | G4: =ROUND(Scenarios!D13,0) -> -1794151 | H4: =IF(ISNUMBER(Scenarios!D14),ROUND(Scenarios!D14,4),"") | I4: =IF(ISNUMBER(Scenarios!D15),ROUND(Scenarios!D15,1),"") | J4: =ROUND(Scenarios!D16,0) -> -1793390 | K4: =ROUND(Scenarios!D17,0) -> 172

Sheet scenario_cash_flows
A1: scenario | B1: year | C1: net_cash_flow | D1: cumulative_cash_flow
